Workbook

Sheet BBRI
A1: Date | B1: Date | C1: Open | D1: High | E1: Low | F1: Close | G1: Volume | H1: Change | I1: Cumulative Return | J1: SMA-20 | K1: SMA-50
A2: =IFERROR(__xludf.DUMMYFUNCTION("""COMPUTED_VALUE"""),45293.6666666666) -> 45293.667 | B2: 45293 | C2: 5650 | D2: 5675 | E2: 5625 | F2: 5675 | G2: 91143100 | H2: 0 | I2: 0
A3: =IFERROR(__xludf.DUMMYFUNCTION("""COMPUTED_VALUE"""),45294.6666666666) -> 45294.667 | B3: 45294 | C3: 5625 | D3: 5650 | E3: 5600 | F3: 5600 | G3: 83659700 | H3: =(F3-F2)/F2 -> -0.013215859 | I3: =(F3-$F$2)/$F$2 -> -0.013215859
A4: =IFERROR(__xludf.DUMMYFUNCTION("""COMPUTED_VALUE"""),45295.6666666666) -> 45295.667 | B4: 45295 | C4: 5600 | D4: 5700 | E4: 5575 | F4: 5700 | G4: 92683500 | H4: =(F4-F3)/F3 -> 0.017857143 | I4: =(F4-$F$2)/$F$2 -> 0.0044052863
A5: =IFERROR(__xludf.DUMMYFUNCTION("""COMPUTED_VALUE"""),45296.6666666666) -> 45296.667 | B5: 45296 | C5: 5725 | D5: 5850 | E5: 5700 | F5: 5750 | G5: 134929600 | H5: =(F5-F4)/F4 -> 0.0087719298 | I5: =(F5-$F$2)/$F$2 -> 0.013215859
A6: =IFERROR(__xludf.DUMMYFUNCTION("""COMPUTED_VALUE"""),45299.6666666666) -> 45299.667 | B6: 45299 | C6: 5750 | D6: 5800 | E6: 5625 | F6: 5625 | G6: 152015000 | H6: =(F6-F5)/F5 -> -0.02173913 | I6: =(F6-$F$2)/$F$2 -> -0.0088105727
A7: =IFERROR(__xludf.DUMMYFUNCTION("""COMPUTED_VALUE"""),45300.6666666666) -> 45300.667 | B7: 45300 | C7: 5625 | D7: 5700 | E7: 5625 | F7: 5700 | G7: 105666200 | H7: =(F7-F6)/F6 -> 0.013333333 | I7: =(F7-$F$2)/$F$2 -> 0.0044052863
A8: =IFERROR(__xludf.DUMMYFUNCTION("""COMPUTED_VALUE"""),45301.6666666666) -> 45301.667 | B8: 45301 | C8: 5625 | D8: 5700 | E8: 5625 | F8: 5700 | G8: 82626400 | H8: =(F8-F7)/F7 -> 0 | I8: =(F8-$F$2)/$F$2 -> 0.0044052863
A9: =IFERROR(__xludf.DUMMYFUNCTION("""COMPUTED_VALUE"""),45302.6666666666) -> 45302.667 | B9: 45302 | C9: 5750 | D9: 5800 | E9: 5700 | F9: 5750 | G9: 116804400 | H9: =(F9-F8)/F8 -> 0.0087719298 | I9: =(F9-$F$2)/$F$2 -> 0.013215859
A10: =IFERROR(__xludf.DUMMYFUNCTION("""COMPUTED_VALUE"""),45303.6666666666) -> 45303.667 | B10: 45303 | C10: 5800 | D10: 5850 | E10: 5775 | F10: 5850 | G10: 109715700 | H10: =(F10-F9)/F9 -> 0.017391304 | I10: =(F10-$F$2)/$F$2 -> 0.030837004
A11: =IFERROR(__xludf.DUMMYFUNCTION("""COMPUTED_VALUE"""),45306.6666666666) -> 45306.667 | B11: 45306 | C11: 5850 | D11: 5900 | E11: 5775 | F11: 5825 | G11: 115126700 | H11: =(F11-F10)/F10 -> -0.0042735043 | I11: =(F11-$F$2)/$F$2 -> 0.026431718
A12: =IFERROR(__xludf.DUMMYFUNCTION("""COMPUTED_VALUE"""),45307.6666666666) -> 45307.667 | B12: 45307 | C12: 5825 | D12: 5875 | E12: 5775 | F12: 5825 | G12: 97074300 | H12: =(F12-F11)/F11 -> 0 | I12: =(F12-$F$2)/$F$2 -> 0.026431718
A13: =IFERROR(__xludf.DUMMYFUNCTION("""COMPUTED_VALUE"""),45308.6666666666) -> 45308.667 | B13: 45308 | C13: 5825 | D13: 5825 | E13: 5750 | F13: 5775 | G13: 107941600 | H13: =(F13-F12)/F12 -> -0.008583691 | I13: =(F13-$F$2)/$F$2 -> 0.017621145
A14: =IFERROR(__xludf.DUMMYFUNCTION("""COMPUTED_VALUE"""),45309.6666666666) -> 45309.667 | B14: 45309 | C14: 5800 | D14: 5800 | E14: 5700 | F14: 5750 | G14: 87259100 | H14: =(F14-F13)/F13 -> -0.0043290043 | I14: =(F14-$F$2)/$F$2 -> 0.013215859
A15: =IFERROR(__xludf.DUMMYFUNCTION("""COMPUTED_VALUE"""),45310.6666666666) -> 45310.667 | B15: 45310 | C15: 5750 | D15: 5800 | E15: 5700 | F15: 5800 | G15: 75370700 | H15: =(F15-F14)/F14 -> 0.0086956522 | I15: =(F15-$F$2)/$F$2 -> 0.022026432
A16: =IFERROR(__xludf.DUMMYFUNCTION("""COMPUTED_VALUE"""),45313.6666666666) -> 45313.667 | B16: 45313 | C16: 5775 | D16: 5800 | E16: 5700 | F16: 5775 | G16: 97545600 | H16: =(F16-F15)/F15 -> -0.0043103448 | I16: =(F16-$F$2)/$F$2 -> 0.017621145
A17: =IFERROR(__xludf.DUMMYFUNCTION("""COMPUTED_VALUE"""),45314.6666666666) -> 45314.667 | B17: 45314 | C17: 5700 | D17: 5750 | E17: 5650 | F17: 5700 | G17: 122999700 | H17: =(F17-F16)/F16 -> -0.012987013 | I17: =(F17-$F$2)/$F$2 -> 0.0044052863
A18: =IFERROR(__xludf.DUMMYFUNCTION("""COMPUTED_VALUE"""),45315.6666666666) -> 45315.667 | B18: 45315 | C18: 5675 | D18: 5700 | E18: 5575 | F18: 5650 | G18: 104225000 | H18: =(F18-F17)/F17 -> -0.0087719298 | I18: =(F18-$F$2)/$F$2 -> -0.0044052863
A19: =IFERROR(__xludf.DUMMYFUNCTION("""COMPUTED_VALUE"""),45316.6666666666) -> 45316.667 | B19: 45316 | C19: 5575 | D19: 5650 | E19: 5525 | F19: 5525 | G19: 120478800 | H19: =(F19-F18)/F18 -> -0.022123894 | I19: =(F19-$F$2)/$F$2 -> -0.026431718
A20: =IFERROR(__xludf.DUMMYFUNCTION("""COMPUTED_VALUE"""),45317.6666666666) -> 45317.667 | B20: 45317 | C20: 5450 | D20: 5475 | E20: 5400 | F20: 5425 | G20: 185244400 | H20: =(F20-F19)/F19 -> -0.018099548 | I20: =(F20-$F$2)/$F$2 -> -0.044052863
A21: =IFERROR(__xludf.DUMMYFUNCTION("""COMPUTED_VALUE"""),45320.6666666666) -> 45320.667 | B21: 45320 | C21: 5400 | D21: 5575 | E21: 5400 | F21: 5575 | G21: 145629600 | H21: =(F21-F20)/F20 -> 0.02764977 | I21: =(F21-$F$2)/$F$2 -> -0.017621145 | J21: =AVERAGE(F2:F21) -> 5698.75
A22: =IFERROR(__xludf.DUMMYFUNCTION("""COMPUTED_VALUE"""),45321.6666666666) -> 45321.667 | B22: 45321 | C22: 5525 | D22: 5650 | E22: 5475 | F22: 5625 | G22: 150513700 | H22: =(F22-F21)/F21 -> 0.0089686099 | I22: =(F22-$F$2)/$F$2 -> -0.0088105727 | J22: =AVERAGE(F3:F22) -> 5696.25
A23: =IFERROR(__xludf.DUMMYFUNCTION("""COMPUTED_VALUE"""),45322.6666666666) -> 45322.667 | B23: 45322 | C23: 5725 | D23: 5775 | E23: 5675 | F23: 5700 | G23: 245117200 | H23: =(F23-F22)/F22 -> 0.013333333 | I23: =(F23-$F$2)/$F$2 -> 0.0044052863 | J23: =AVERAGE(F4:F23) -> 5701.25
A24: =IFERROR(__xludf.DUMMYFUNCTION("""COMPUTED_VALUE"""),45323.6666666666) -> 45323.667 | B24: 45323 | C24: 5775 | D24: 5800 | E24: 5725 | F24: 5750 | G24: 156633900 | H24: =(F24-F23)/F23 -> 0.0087719298 | I24: =(F24-$F$2)/$F$2 -> 0.013215859 | J24: =AVERAGE(F5:F24) -> 5703.75
A25: =IFERROR(__xludf.DUMMYFUNCTION("""COMPUTED_VALUE"""),45324.6666666666) -> 45324.667 | B25: 45324 | C25: 5800 | D25: 5850 | E25: 5750 | F25: 5850 | G25: 177209700 | H25: =(F25-F24)/F24 -> 0.017391304 | I25: =(F25-$F$2)/$F$2 -> 0.030837004 | J25: =AVERAGE(F6:F25) -> 5708.75
A26: =IFERROR(__xludf.DUMMYFUNCTION("""COMPUTED_VALUE"""),45327.6666666666) -> 45327.667 | B26: 45327 | C26: 5800 | D26: 5825 | E26: 5750 | F26: 5775 | G26: 113760000 | H26: =(F26-F25)/F25 -> -0.012820513 | I26: =(F26-$F$2)/$F$2 -> 0.017621145 | J26: =AVERAGE(F7:F26) -> 5716.25
A27: =IFERROR(__xludf.DUMMYFUNCTION("""COMPUTED_VALUE"""),45328.6666666666) -> 45328.667 | B27: 45328 | C27: 5900 | D27: 5900 | E27: 5800 | F27: 5825 | G27: 126704300 | H27: =(F27-F26)/F26 -> 0.0086580087 | I27: =(F27-$F$2)/$F$2 -> 0.026431718 | J27: =AVERAGE(F8:F27) -> 5722.5
A28: =IFERROR(__xludf.DUMMYFUNCTION("""COMPUTED_VALUE"""),45329.6666666666) -> 45329.667 | B28: 45329 | C28: 5850 | D28: 5900 | E28: 5825 | F28: 5850 | G28: 147005300 | H28: =(F28-F27)/F27 -> 0.0042918455 | I28: =(F28-$F$2)/$F$2 -> 0.030837004 | J28: =AVERAGE(F9:F28) -> 5730
A29: =IFERROR(__xludf.DUMMYFUNCTION("""COMPUTED_VALUE"""),45334.6666666666) -> 45334.667 | B29: 45334 | C29: 5875 | D29: 6025 | E29: 5850 | F29: 6025 | G29: 171514600 | H29: =(F29-F28)/F28 -> 0.02991453 | I29: =(F29-$F$2)/$F$2 -> 0.061674009 | J29: =AVERAGE(F10:F29) -> 5743.75
A30: =IFERROR(__xludf.DUMMYFUNCTION("""COMPUTED_VALUE"""),45335.6666666666) -> 45335.667 | B30: 45335 | C30: 6050 | D30: 6050 | E30: 5950 | F30: 6000 | G30: 145852200 | H30: =(F30-F29)/F29 -> -0.0041493776 | I30: =(F30-$F$2)/$F$2 -> 0.057268722 | J30: =AVERAGE(F11:F30) -> 5751.25
A31: =IFERROR(__xludf.DUMMYFUNCTION("""COMPUTED_VALUE"""),45337.6666666666) -> 45337.667 | B31: 45337 | C31: 6275 | D31: 6275 | E31: 6100 | F31: 6125 | G31: 308685100 | H31: =(F31-F30)/F30 -> 0.020833333 | I31: =(F31-$F$2)/$F$2 -> 0.079295154 | J31: =AVERAGE(F12:F31) -> 5766.25
A32: =IFERROR(__xludf.DUMMYFUNCTION("""COMPUTED_VALUE"""),45338.6666666666) -> 45338.667 | B32: 45338 | C32: 6150 | D32: 6200 | E32: 6125 | F32: 6150 | G32: 130814400 | H32: =(F32-F31)/F31 -> 0.0040816327 | I32: =(F32-$F$2)/$F$2 -> 0.083700441 | J32: =AVERAGE(F13:F32) -> 5782.5
A33: =IFERROR(__xludf.DUMMYFUNCTION("""COMPUTED_VALUE"""),45341.6666666666) -> 45341.667 | B33: 45341 | C33: 6125 | D33: 6175 | E33: 6075 | F33: 6100 | G33: 111382900 | H33: =(F33-F32)/F32 -> -0.0081300813 | I33: =(F33-$F$2)/$F$2 -> 0.074889868 | J33: =AVERAGE(F14:F33) -> 5798.75
A34: =IFERROR(__xludf.DUMMYFUNCTION("""COMPUTED_VALUE"""),45342.6666666666) -> 45342.667 | B34: 45342 | C34: 6175 | D34: 6300 | E34: 6175 | F34: 6300 | G34: 160872600 | H34: =(F34-F33)/F33 -> 0.032786885 | I34: =(F34-$F$2)/$F$2 -> 0.11013216 | J34: =AVERAGE(F15:F34) -> 5826.25
A35: =IFERROR(__xludf.DUMMYFUNCTION("""COMPUTED_VALUE"""),45343.6666666666) -> 45343.667 | B35: 45343 | C35: 6325 | D35: 6375 | E35: 6225 | F35: 6300 | G35: 168423000 | H35: =(F35-F34)/F34 -> 0 | I35: =(F35-$F$2)/$F$2 -> 0.11013216 | J35: =AVERAGE(F16:F35) -> 5851.25
A36: =IFERROR(__xludf.DUMMYFUNCTION("""COMPUTED_VALUE"""),45344.6666666666) -> 45344.667 | B36: 45344 | C36: 6250 | D36: 6300 | E36: 6225 | F36: 6250 | G36: 100256000 | H36: =(F36-F35)/F35 -> -0.0079365079 | I36: =(F36-$F$2)/$F$2 -> 0.10132159 | J36: =AVERAGE(F17:F36) -> 5875
A37: =IFERROR(__xludf.DUMMYFUNCTION("""COMPUTED_VALUE"""),45345.6666666666) -> 45345.667 | B37: 45345 | C37: 6125 | D37: 6175 | E37: 6050 | F37: 6125 | G37: 148643000 | H37: =(F37-F36)/F36 -> -0.02 | I37: =(F37-$F$2)/$F$2 -> 0.079295154 | J37: =AVERAGE(F18:F37) -> 5896.25
A38: =IFERROR(__xludf.DUMMYFUNCTION("""COMPUTED_VALUE"""),45348.6666666666) -> 45348.667 | B38: 45348 | C38: 6100 | D38: 6200 | E38: 6075 | F38: 6175 | G38: 98920800 | H38: =(F38-F37)/F37 -> 0.0081632653 | I38: =(F38-$F$2)/$F$2 -> 0.088105727 | J38: =AVERAGE(F19:F38) -> 5922.5
A39: =IFERROR(__xludf.DUMMYFUNCTION("""COMPUTED_VALUE"""),45349.6666666666) -> 45349.667 | B39: 45349 | C39: 6125 | D39: 6200 | E39: 6125 | F39: 6125 | G39: 99187500 | H39: =(F39-F38)/F38 -> -0.008097166 | I39: =(F39-$F$2)/$F$2 -> 0.079295154 | J39: =AVERAGE(F20:F39) -> 5952.5
A40: =IFERROR(__xludf.DUMMYFUNCTION("""COMPUTED_VALUE"""),45350.6666666666) -> 45350.667 | B40: 45350 | C40: 6100 | D40: 6225 | E40: 6100 | F40: 6225 | G40: 97236700 | H40: =(F40-F39)/F39 -> 0.016326531 | I40: =(F40-$F$2)/$F$2 -> 0.0969163 | J40: =AVERAGE(F21:F40) -> 5992.5
...

Sheet BBCA
A1: Date | C1: Open | D1: High | E1: Low | F1: Close | G1: Volume | H1: Change
A2: =IFERROR(__xludf.DUMMYFUNCTION("""COMPUTED_VALUE"""),45293.6666666666) -> 45293.667 | C2: 9400 | D2: 9425 | E2: 9350 | F2: 9425 | G2: 30545200 | H2: 0 | I2: 0
A3: =IFERROR(__xludf.DUMMYFUNCTION("""COMPUTED_VALUE"""),45294.6666666666) -> 45294.667 | C3: 9425 | D3: 9425 | E3: 9325 | F3: 9350 | G3: 34603300 | H3: =(F3-F2)/F2 -> -0.0079575597 | I3: =(F3-$F$2)/$F$2 -> -0.0079575597
A4: =IFERROR(__xludf.DUMMYFUNCTION("""COMPUTED_VALUE"""),45295.6666666666) -> 45295.667 | C4: 9400 | D4: 9475 | E4: 9375 | F4: 9475 | G4: 56501800 | H4: =(F4-F3)/F3 -> 0.013368984 | I4: =(F4-$F$2)/$F$2 -> 0.0053050398
A5: =IFERROR(__xludf.DUMMYFUNCTION("""COMPUTED_VALUE"""),45296.6666666666) -> 45296.667 | C5: 9500 | D5: 9600 | E5: 9475 | F5: 9575 | G5: 85290100 | H5: =(F5-F4)/F4 -> 0.01055409 | I5: =(F5-$F$2)/$F$2 -> 0.015915119
A6: =IFERROR(__xludf.DUMMYFUNCTION("""COMPUTED_VALUE"""),45299.6666666666) -> 45299.667 | C6: 9600 | D6: 9625 | E6: 9475 | F6: 9575 | G6: 50896000 | H6: =(F6-F5)/F5 -> 0 | I6: =(F6-$F$2)/$F$2 -> 0.015915119
A7: =IFERROR(__xludf.DUMMYFUNCTION("""COMPUTED_VALUE"""),45300.6666666666) -> 45300.667 | C7: 9600 | D7: 9625 | E7: 9575 | F7: 9625 | G7: 59848600 | H7: =(F7-F6)/F6 -> 0.0052219321 | I7: =(F7-$F$2)/$F$2 -> 0.021220159
A8: =IFERROR(__xludf.DUMMYFUNCTION("""COMPUTED_VALUE"""),45301.6666666666) -> 45301.667 | C8: 9650 | D8: 9650 | E8: 9550 | F8: 9550 | G8: 52774900 | H8: =(F8-F7)/F7 -> -0.0077922078 | I8: =(F8-$F$2)/$F$2 -> 0.013262599
A9: =IFERROR(__xludf.DUMMYFUNCTION("""COMPUTED_VALUE"""),45302.6666666666) -> 45302.667 | C9: 9625 | D9: 9650 | E9: 9575 | F9: 9575 | G9: 39381500 | H9: =(F9-F8)/F8 -> 0.002617801 | I9: =(F9-$F$2)/$F$2 -> 0.015915119
A10: =IFERROR(__xludf.DUMMYFUNCTION("""COMPUTED_VALUE"""),45303.6666666666) -> 45303.667 | C10: 9650 | D10: 9700 | E10: 9600 | F10: 9700 | G10: 68253400 | H10: =(F10-F9)/F9 -> 0.01305483 | I10: =(F10-$F$2)/$F$2 -> 0.029177719
A11: =IFERROR(__xludf.DUMMYFUNCTION("""COMPUTED_VALUE"""),45306.6666666666) -> 45306.667 | C11: 9750 | D11: 9750 | E11: 9650 | F11: 9725 | G11: 88399500 | H11: =(F11-F10)/F10 -> 0.0025773196 | I11: =(F11-$F$2)/$F$2 -> 0.031830239
A12: =IFERROR(__xludf.DUMMYFUNCTION("""COMPUTED_VALUE"""),45307.6666666666) -> 45307.667 | C12: 9700 | D12: 9750 | E12: 9675 | F12: 9700 | G12: 44869200 | H12: =(F12-F11)/F11 -> -0.0025706941 | I12: =(F12-$F$2)/$F$2 -> 0.029177719
A13: =IFERROR(__xludf.DUMMYFUNCTION("""COMPUTED_VALUE"""),45308.6666666666) -> 45308.667 | C13: 9750 | D13: 9750 | E13: 9650 | F13: 9750 | G13: 107706100 | H13: =(F13-F12)/F12 -> 0.0051546392 | I13: =(F13-$F$2)/$F$2 -> 0.034482759
A14: =IFERROR(__xludf.DUMMYFUNCTION("""COMPUTED_VALUE"""),45309.6666666666) -> 45309.667 | C14: 9675 | D14: 9750 | E14: 9625 | F14: 9675 | G14: 71048900 | H14: =(F14-F13)/F13 -> -0.0076923077 | I14: =(F14-$F$2)/$F$2 -> 0.026525199
A15: =IFERROR(__xludf.DUMMYFUNCTION("""COMPUTED_VALUE"""),45310.6666666666) -> 45310.667 | C15: 9775 | D15: 9775 | E15: 9600 | F15: 9625 | G15: 63176500 | H15: =(F15-F14)/F14 -> -0.0051679587 | I15: =(F15-$F$2)/$F$2 -> 0.021220159
A16: =IFERROR(__xludf.DUMMYFUNCTION("""COMPUTED_VALUE"""),45313.6666666666) -> 45313.667 | C16: 9600 | D16: 9650 | E16: 9525 | F16: 9625 | G16: 52868300 | H16: =(F16-F15)/F15 -> 0 | I16: =(F16-$F$2)/$F$2 -> 0.021220159
A17: =IFERROR(__xludf.DUMMYFUNCTION("""COMPUTED_VALUE"""),45314.6666666666) -> 45314.667 | C17: 9450 | D17: 9600 | E17: 9450 | F17: 9600 | G17: 92348600 | H17: =(F17-F16)/F16 -> -0.0025974026 | I17: =(F17-$F$2)/$F$2 -> 0.018567639
A18: =IFERROR(__xludf.DUMMYFUNCTION("""COMPUTED_VALUE"""),45315.6666666666) -> 45315.667 | C18: 9600 | D18: 9600 | E18: 9475 | F18: 9525 | G18: 84906000 | H18: =(F18-F17)/F17 -> -0.0078125 | I18: =(F18-$F$2)/$F$2 -> 0.01061008
A19: =IFERROR(__xludf.DUMMYFUNCTION("""COMPUTED_VALUE"""),45316.6666666666) -> 45316.667 | C19: 9450 | D19: 9575 | E19: 9450 | F19: 9500 | G19: 63212700 | H19: =(F19-F18)/F18 -> -0.0026246719 | I19: =(F19-$F$2)/$F$2 -> 0.0079575597
A20: =IFERROR(__xludf.DUMMYFUNCTION("""COMPUTED_VALUE"""),45317.6666666666) -> 45317.667 | C20: 9400 | D20: 9450 | E20: 9300 | F20: 9350 | G20: 78977300 | H20: =(F20-F19)/F19 -> -0.015789474 | I20: =(F20-$F$2)/$F$2 -> -0.0079575597
A21: =IFERROR(__xludf.DUMMYFUNCTION("""COMPUTED_VALUE"""),45320.6666666666) -> 45320.667 | C21: 9400 | D21: 9550 | E21: 9375 | F21: 9550 | G21: 73452800 | H21: =(F21-F20)/F20 -> 0.021390374 | I21: =(F21-$F$2)/$F$2 -> 0.013262599 | J21: =AVERAGE(F2:F21) -> 9573.75
A22: =IFERROR(__xludf.DUMMYFUNCTION("""COMPUTED_VALUE"""),45321.6666666666) -> 45321.667 | C22: 9500 | D22: 9650 | E22: 9475 | F22: 9650 | G22: 73136400 | H22: =(F22-F21)/F21 -> 0.010471204 | I22: =(F22-$F$2)/$F$2 -> 0.023872679 | J22: =AVERAGE(F3:F22) -> 9585
A23: =IFERROR(__xludf.DUMMYFUNCTION("""COMPUTED_VALUE"""),45322.6666666666) -> 45322.667 | C23: 9700 | D23: 9700 | E23: 9550 | F23: 9550 | G23: 102581200 | H23: =(F23-F22)/F22 -> -0.010362694 | I23: =(F23-$F$2)/$F$2 -> 0.013262599 | J23: =AVERAGE(F4:F23) -> 9595
A24: =IFERROR(__xludf.DUMMYFUNCTION("""COMPUTED_VALUE"""),45323.6666666666) -> 45323.667 | C24: 9650 | D24: 9725 | E24: 9575 | F24: 9700 | G24: 104208700 | H24: =(F24-F23)/F23 -> 0.015706806 | I24: =(F24-$F$2)/$F$2 -> 0.029177719 | J24: =AVERAGE(F5:F24) -> 9606.25
A25: =IFERROR(__xludf.DUMMYFUNCTION("""COMPUTED_VALUE"""),45324.6666666666) -> 45324.667 | C25: 9775 | D25: 9800 | E25: 9625 | F25: 9700 | G25: 99324000 | H25: =(F25-F24)/F24 -> 0 | I25: =(F25-$F$2)/$F$2 -> 0.029177719 | J25: =AVERAGE(F6:F25) -> 9612.5
A26: =IFERROR(__xludf.DUMMYFUNCTION("""COMPUTED_VALUE"""),45327.6666666666) -> 45327.667 | C26: 9675 | D26: 9675 | E26: 9525 | F26: 9575 | G26: 57983300 | H26: =(F26-F25)/F25 -> -0.012886598 | I26: =(F26-$F$2)/$F$2 -> 0.015915119 | J26: =AVERAGE(F7:F26) -> 9612.5
A27: =IFERROR(__xludf.DUMMYFUNCTION("""COMPUTED_VALUE"""),45328.6666666666) -> 45328.667 | C27: 9750 | D27: 9750 | E27: 9625 | F27: 9625 | G27: 87651000 | H27: =(F27-F26)/F26 -> 0.0052219321 | I27: =(F27-$F$2)/$F$2 -> 0.021220159 | J27: =AVERAGE(F8:F27) -> 9612.5
A28: =IFERROR(__xludf.DUMMYFUNCTION("""COMPUTED_VALUE"""),45329.6666666666) -> 45329.667 | C28: 9700 | D28: 9725 | E28: 9650 | F28: 9700 | G28: 92953500 | H28: =(F28-F27)/F27 -> 0.0077922078 | I28: =(F28-$F$2)/$F$2 -> 0.029177719 | J28: =AVERAGE(F9:F28) -> 9620
A29: =IFERROR(__xludf.DUMMYFUNCTION("""COMPUTED_VALUE"""),45334.6666666666) -> 45334.667 | C29: 9750 | D29: 9800 | E29: 9700 | F29: 9800 | G29: 87949400 | H29: =(F29-F28)/F28 -> 0.010309278 | I29: =(F29-$F$2)/$F$2 -> 0.039787798 | J29: =AVERAGE(F10:F29) -> 9631.25
A30: =IFERROR(__xludf.DUMMYFUNCTION("""COMPUTED_VALUE"""),45335.6666666666) -> 45335.667 | C30: 9750 | D30: 9800 | E30: 9700 | F30: 9725 | G30: 66072400 | H30: =(F30-F29)/F29 -> -0.0076530612 | I30: =(F30-$F$2)/$F$2 -> 0.031830239 | J30: =AVERAGE(F11:F30) -> 9632.5
A31: =IFERROR(__xludf.DUMMYFUNCTION("""COMPUTED_VALUE"""),45337.6666666666) -> 45337.667 | C31: 9950 | D31: 9975 | E31: 9850 | F31: 9850 | G31: 164748900 | H31: =(F31-F30)/F30 -> 0.01285347 | I31: =(F31-$F$2)/$F$2 -> 0.045092838 | J31: =AVERAGE(F12:F31) -> 9638.75
A32: =IFERROR(__xludf.DUMMYFUNCTION("""COMPUTED_VALUE"""),45338.6666666666) -> 45338.667 | C32: 9975 | D32: 10000 | E32: 9875 | F32: 9950 | G32: 142277200 | H32: =(F32-F31)/F31 -> 0.010152284 | I32: =(F32-$F$2)/$F$2 -> 0.055702918 | J32: =AVERAGE(F13:F32) -> 9651.25
A33: =IFERROR(__xludf.DUMMYFUNCTION("""COMPUTED_VALUE"""),45341.6666666666) -> 45341.667 | C33: 9900 | D33: 9975 | E33: 9825 | F33: 9875 | G33: 53341300 | H33: =(F33-F32)/F32 -> -0.0075376884 | I33: =(F33-$F$2)/$F$2 -> 0.047745358 | J33: =AVERAGE(F14:F33) -> 9657.5
A34: =IFERROR(__xludf.DUMMYFUNCTION("""COMPUTED_VALUE"""),45342.6666666666) -> 45342.667 | C34: 9850 | D34: 10025 | E34: 9850 | F34: 10025 | G34: 63997700 | H34: =(F34-F33)/F33 -> 0.015189873 | I34: =(F34-$F$2)/$F$2 -> 0.063660477 | J34: =AVERAGE(F15:F34) -> 9675
A35: =IFERROR(__xludf.DUMMYFUNCTION("""COMPUTED_VALUE"""),45343.6666666666) -> 45343.667 | C35: 9950 | D35: 10000 | E35: 9850 | F35: 9975 | G35: 75371600 | H35: =(F35-F34)/F34 -> -0.0049875312 | I35: =(F35-$F$2)/$F$2 -> 0.058355438 | J35: =AVERAGE(F16:F35) -> 9692.5
A36: =IFERROR(__xludf.DUMMYFUNCTION("""COMPUTED_VALUE"""),45344.6666666666) -> 45344.667 | C36: 9975 | D36: 9975 | E36: 9875 | F36: 9875 | G36: 66913000 | H36: =(F36-F35)/F35 -> -0.010025063 | I36: =(F36-$F$2)/$F$2 -> 0.047745358 | J36: =AVERAGE(F17:F36) -> 9705
A37: =IFERROR(__xludf.DUMMYFUNCTION("""COMPUTED_VALUE"""),45345.6666666666) -> 45345.667 | C37: 9900 | D37: 9925 | E37: 9800 | F37: 9825 | G37: 55192300 | H37: =(F37-F36)/F36 -> -0.0050632911 | I37: =(F37-$F$2)/$F$2 -> 0.042440318 | J37: =AVERAGE(F18:F37) -> 9716.25
A38: =IFERROR(__xludf.DUMMYFUNCTION("""COMPUTED_VALUE"""),45348.6666666666) -> 45348.667 | C38: 9750 | D38: 9875 | E38: 9725 | F38: 9800 | G38: 41356000 | H38: =(F38-F37)/F37 -> -0.0025445293 | I38: =(F38-$F$2)/$F$2 -> 0.039787798 | J38: =AVERAGE(F19:F38) -> 9730
A39: =IFERROR(__xludf.DUMMYFUNCTION("""COMPUTED_VALUE"""),45349.6666666666) -> 45349.667 | C39: 9750 | D39: 9900 | E39: 9750 | F39: 9875 | G39: 43735800 | H39: =(F39-F38)/F38 -> 0.0076530612 | I39: =(F39-$F$2)/$F$2 -> 0.047745358 | J39: =AVERAGE(F20:F39) -> 9748.75
A40: =IFERROR(__xludf.DUMMYFUNCTION("""COMPUTED_VALUE"""),45350.6666666666) -> 45350.667 | C40: 9975 | D40: 10000 | E40: 9900 | F40: 10000 | G40: 54043100 | H40: =(F40-F39)/F39 -> 0.012658228 | I40: =(F40-$F$2)/$F$2 -> 0.061007958 | J40: =AVERAGE(F21:F40) -> 9781.25
...

Sheet BMRI
A1: Date | C1: Open | D1: High | E1: Low | F1: Close | G1: Volume | H1: Change
A2: =IFERROR(__xludf.DUMMYFUNCTION("""COMPUTED_VALUE"""),45293.6666666666) -> 45293.667 | C2: 6050 | D2: 6125 | E2: 6025 | F2: 6125 | G2: 26235700 | H2: 0 | I2: 0
A3: =IFERROR(__xludf.DUMMYFUNCTION("""COMPUTED_VALUE"""),45294.6666666666) -> 45294.667 | C3: 6100 | D3: 6150 | E3: 6050 | F3: 6100 | G3: 30053900 | H3: =(F3-F2)/F2 -> -0.0040816327 | I3: =(F3-$F$2)/$F$2 -> -0.0040816327
A4: =IFERROR(__xludf.DUMMYFUNCTION("""COMPUTED_VALUE"""),45295.6666666666) -> 45295.667 | C4: 6125 | D4: 6400 | E4: 6100 | F4: 6350 | G4: 135344500 | H4: =(F4-F3)/F3 -> 0.040983607 | I4: =(F4-$F$2)/$F$2 -> 0.036734694
A5: =IFERROR(__xludf.DUMMYFUNCTION("""COMPUTED_VALUE"""),45296.6666666666) -> 45296.667 | C5: 6400 | D5: 6475 | E5: 6350 | F5: 6425 | G5: 114339400 | H5: =(F5-F4)/F4 -> 0.011811024 | I5: =(F5-$F$2)/$F$2 -> 0.048979592
A6: =IFERROR(__xludf.DUMMYFUNCTION("""COMPUTED_VALUE"""),45299.6666666666) -> 45299.667 | C6: 6500 | D6: 6600 | E6: 6375 | F6: 6400 | G6: 151018300 | H6: =(F6-F5)/F5 -> -0.0038910506 | I6: =(F6-$F$2)/$F$2 -> 0.044897959
A7: =IFERROR(__xludf.DUMMYFUNCTION("""COMPUTED_VALUE"""),45300.6666666666) -> 45300.667 | C7: 6425 | D7: 6450 | E7: 6350 | F7: 6375 | G7: 77953400 | H7: =(F7-F6)/F6 -> -0.00390625 | I7: =(F7-$F$2)/$F$2 -> 0.040816327
A8: =IFERROR(__xludf.DUMMYFUNCTION("""COMPUTED_VALUE"""),45301.6666666666) -> 45301.667 | C8: 6375 | D8: 6450 | E8: 6325 | F8: 6425 | G8: 50019800 | H8: =(F8-F7)/F7 -> 0.0078431373 | I8: =(F8-$F$2)/$F$2 -> 0.048979592
A9: =IFERROR(__xludf.DUMMYFUNCTION("""COMPUTED_VALUE"""),45302.6666666666) -> 45302.667 | C9: 6425 | D9: 6500 | E9: 6400 | F9: 6450 | G9: 32120200 | H9: =(F9-F8)/F8 -> 0.0038910506 | I9: =(F9-$F$2)/$F$2 -> 0.053061224
A10: =IFERROR(__xludf.DUMMYFUNCTION("""COMPUTED_VALUE"""),45303.6666666666) -> 45303.667 | C10: 6575 | D10: 6675 | E10: 6525 | F10: 6575 | G10: 114039700 | H10: =(F10-F9)/F9 -> 0.019379845 | I10: =(F10-$F$2)/$F$2 -> 0.073469388
A11: =IFERROR(__xludf.DUMMYFUNCTION("""COMPUTED_VALUE"""),45306.6666666666) -> 45306.667 | C11: 6575 | D11: 6625 | E11: 6475 | F11: 6500 | G11: 83066800 | H11: =(F11-F10)/F10 -> -0.011406844 | I11: =(F11-$F$2)/$F$2 -> 0.06122449
A12: =IFERROR(__xludf.DUMMYFUNCTION("""COMPUTED_VALUE"""),45307.6666666666) -> 45307.667 | C12: 6525 | D12: 6625 | E12: 6500 | F12: 6525 | G12: 83516800 | H12: =(F12-F11)/F11 -> 0.0038461538 | I12: =(F12-$F$2)/$F$2 -> 0.065306122
A13: =IFERROR(__xludf.DUMMYFUNCTION("""COMPUTED_VALUE"""),45308.6666666666) -> 45308.667 | C13: 6525 | D13: 6625 | E13: 6500 | F13: 6525 | G13: 80929000 | H13: =(F13-F12)/F12 -> 0 | I13: =(F13-$F$2)/$F$2 -> 0.065306122
A14: =IFERROR(__xludf.DUMMYFUNCTION("""COMPUTED_VALUE"""),45309.6666666666) -> 45309.667 | C14: 6525 | D14: 6550 | E14: 6475 | F14: 6525 | G14: 78209900 | H14: =(F14-F13)/F13 -> 0 | I14: =(F14-$F$2)/$F$2 -> 0.065306122
A15: =IFERROR(__xludf.DUMMYFUNCTION("""COMPUTED_VALUE"""),45310.6666666666) -> 45310.667 | C15: 6500 | D15: 6525 | E15: 6425 | F15: 6525 | G15: 74814000 | H15: =(F15-F14)/F14 -> 0 | I15: =(F15-$F$2)/$F$2 -> 0.065306122
A16: =IFERROR(__xludf.DUMMYFUNCTION("""COMPUTED_VALUE"""),45313.6666666666) -> 45313.667 | C16: 6500 | D16: 6550 | E16: 6450 | F16: 6500 | G16: 96993100 | H16: =(F16-F15)/F15 -> -0.0038314176 | I16: =(F16-$F$2)/$F$2 -> 0.06122449
A17: =IFERROR(__xludf.DUMMYFUNCTION("""COMPUTED_VALUE"""),45314.6666666666) -> 45314.667 | C17: 6525 | D17: 6550 | E17: 6450 | F17: 6500 | G17: 77037800 | H17: =(F17-F16)/F16 -> 0 | I17: =(F17-$F$2)/$F$2 -> 0.06122449
A18: =IFERROR(__xludf.DUMMYFUNCTION("""COMPUTED_VALUE"""),45315.6666666666) -> 45315.667 | C18: 6450 | D18: 6475 | E18: 6350 | F18: 6400 | G18: 97290600 | H18: =(F18-F17)/F17 -> -0.015384615 | I18: =(F18-$F$2)/$F$2 -> 0.044897959
A19: =IFERROR(__xludf.DUMMYFUNCTION("""COMPUTED_VALUE"""),45316.6666666666) -> 45316.667 | C19: 6325 | D19: 6400 | E19: 6250 | F19: 6275 | G19: 99094100 | H19: =(F19-F18)/F18 -> -0.01953125 | I19: =(F19-$F$2)/$F$2 -> 0.024489796
A20: =IFERROR(__xludf.DUMMYFUNCTION("""COMPUTED_VALUE"""),45317.6666666666) -> 45317.667 | C20: 6250 | D20: 6325 | E20: 6225 | F20: 6300 | G20: 77236800 | H20: =(F20-F19)/F19 -> 0.0039840637 | I20: =(F20-$F$2)/$F$2 -> 0.028571429
A21: =IFERROR(__xludf.DUMMYFUNCTION("""COMPUTED_VALUE"""),45320.6666666666) -> 45320.667 | C21: 6350 | D21: 6475 | E21: 6275 | F21: 6475 | G21: 124753000 | H21: =(F21-F20)/F20 -> 0.027777778 | I21: =(F21-$F$2)/$F$2 -> 0.057142857
A22: =IFERROR(__xludf.DUMMYFUNCTION("""COMPUTED_VALUE"""),45321.6666666666) -> 45321.667 | C22: 6475 | D22: 6700 | E22: 6450 | F22: 6650 | G22: 123330900 | H22: =(F22-F21)/F21 -> 0.027027027 | I22: =(F22-$F$2)/$F$2 -> 0.085714286
A23: =IFERROR(__xludf.DUMMYFUNCTION("""COMPUTED_VALUE"""),45322.6666666666) -> 45322.667 | C23: 6650 | D23: 6700 | E23: 6650 | F23: 6650 | G23: 128185000 | H23: =(F23-F22)/F22 -> 0 | I23: =(F23-$F$2)/$F$2 -> 0.085714286
A24: =IFERROR(__xludf.DUMMYFUNCTION("""COMPUTED_VALUE"""),45323.6666666666) -> 45323.667 | C24: 6575 | D24: 6625 | E24: 6500 | F24: 6550 | G24: 168145800 | H24: =(F24-F23)/F23 -> -0.015037594 | I24: =(F24-$F$2)/$F$2 -> 0.069387755
A25: =IFERROR(__xludf.DUMMYFUNCTION("""COMPUTED_VALUE"""),45324.6666666666) -> 45324.667 | C25: 6625 | D25: 6675 | E25: 6600 | F25: 6675 | G25: 120116200 | H25: =(F25-F24)/F24 -> 0.019083969 | I25: =(F25-$F$2)/$F$2 -> 0.089795918
A26: =IFERROR(__xludf.DUMMYFUNCTION("""COMPUTED_VALUE"""),45327.6666666666) -> 45327.667 | C26: 6700 | D26: 6950 | E26: 6675 | F26: 6825 | G26: 150535100 | H26: =(F26-F25)/F25 -> 0.02247191 | I26: =(F26-$F$2)/$F$2 -> 0.11428571
A27: =IFERROR(__xludf.DUMMYFUNCTION("""COMPUTED_VALUE"""),45328.6666666666) -> 45328.667 | C27: 6825 | D27: 6925 | E27: 6775 | F27: 6850 | G27: 90146000 | H27: =(F27-F26)/F26 -> 0.0036630037 | I27: =(F27-$F$2)/$F$2 -> 0.11836735
A28: =IFERROR(__xludf.DUMMYFUNCTION("""COMPUTED_VALUE"""),45329.6666666666) -> 45329.667 | C28: 6875 | D28: 6950 | E28: 6850 | F28: 6950 | G28: 88745500 | H28: =(F28-F27)/F27 -> 0.01459854 | I28: =(F28-$F$2)/$F$2 -> 0.13469388
A29: =IFERROR(__xludf.DUMMYFUNCTION("""COMPUTED_VALUE"""),45334.6666666666) -> 45334.667 | C29: 7150 | D29: 7200 | E29: 7050 | F29: 7100 | G29: 162771300 | H29: =(F29-F28)/F28 -> 0.021582734 | I29: =(F29-$F$2)/$F$2 -> 0.15918367
A30: =IFERROR(__xludf.DUMMYFUNCTION("""COMPUTED_VALUE"""),45335.6666666666) -> 45335.667 | C30: 7100 | D30: 7125 | E30: 7025 | F30: 7025 | G30: 102668900 | H30: =(F30-F29)/F29 -> -0.01056338 | I30: =(F30-$F$2)/$F$2 -> 0.14693878
A31: =IFERROR(__xludf.DUMMYFUNCTION("""COMPUTED_VALUE"""),45337.6666666666) -> 45337.667 | C31: 7300 | D31: 7375 | E31: 7150 | F31: 7200 | G31: 220530000 | H31: =(F31-F30)/F30 -> 0.024911032 | I31: =(F31-$F$2)/$F$2 -> 0.1755102
A32: =IFERROR(__xludf.DUMMYFUNCTION("""COMPUTED_VALUE"""),45338.6666666666) -> 45338.667 | C32: 7375 | D32: 7400 | E32: 7200 | F32: 7200 | G32: 142022100 | H32: =(F32-F31)/F31 -> 0 | I32: =(F32-$F$2)/$F$2 -> 0.1755102
A33: =IFERROR(__xludf.DUMMYFUNCTION("""COMPUTED_VALUE"""),45341.6666666666) -> 45341.667 | C33: 7150 | D33: 7325 | E33: 7125 | F33: 7150 | G33: 83753500 | H33: =(F33-F32)/F32 -> -0.0069444444 | I33: =(F33-$F$2)/$F$2 -> 0.16734694
A34: =IFERROR(__xludf.DUMMYFUNCTION("""COMPUTED_VALUE"""),45342.6666666666) -> 45342.667 | C34: 7250 | D34: 7250 | E34: 7150 | F34: 7150 | G34: 87312000 | H34: =(F34-F33)/F33 -> 0 | I34: =(F34-$F$2)/$F$2 -> 0.16734694
A35: =IFERROR(__xludf.DUMMYFUNCTION("""COMPUTED_VALUE"""),45343.6666666666) -> 45343.667 | C35: 7125 | D35: 7250 | E35: 7075 | F35: 7250 | G35: 128063900 | H35: =(F35-F34)/F34 -> 0.013986014 | I35: =(F35-$F$2)/$F$2 -> 0.18367347
A36: =IFERROR(__xludf.DUMMYFUNCTION("""COMPUTED_VALUE"""),45344.6666666666) -> 45344.667 | C36: 7175 | D36: 7200 | E36: 7100 | F36: 7100 | G36: 85735800 | H36: =(F36-F35)/F35 -> -0.020689655 | I36: =(F36-$F$2)/$F$2 -> 0.15918367
A37: =IFERROR(__xludf.DUMMYFUNCTION("""COMPUTED_VALUE"""),45345.6666666666) -> 45345.667 | C37: 7050 | D37: 7100 | E37: 7000 | F37: 7050 | G37: 109404700 | H37: =(F37-F36)/F36 -> -0.0070422535 | I37: =(F37-$F$2)/$F$2 -> 0.15102041
A38: =IFERROR(__xludf.DUMMYFUNCTION("""COMPUTED_VALUE"""),45348.6666666666) -> 45348.667 | C38: 6950 | D38: 7075 | E38: 6950 | F38: 7050 | G38: 65407700 | H38: =(F38-F37)/F37 -> 0 | I38: =(F38-$F$2)/$F$2 -> 0.15102041
A39: =IFERROR(__xludf.DUMMYFUNCTION("""COMPUTED_VALUE"""),45349.6666666666) -> 45349.667 | C39: 6975 | D39: 7100 | E39: 6975 | F39: 7075 | G39: 58066100 | H39: =(F39-F38)/F38 -> 0.0035460993 | I39: =(F39-$F$2)/$F$2 -> 0.15510204
A40: =IFERROR(__xludf.DUMMYFUNCTION("""COMPUTED_VALUE"""),45350.6666666666) -> 45350.667 | C40: 7025 | D40: 7125 | E40: 7025 | F40: 7125 | G40: 49888400 | H40: =(F40-F39)/F39 -> 0.0070671378 | I40: =(F40-$F$2)/$F$2 -> 0.16326531
...

Sheet BBNI
A1: Date | C1: Open | D1: High | E1: Low | F1: Close | G1: Volume | H1: Change
A2: =IFERROR(__xludf.DUMMYFUNCTION("""COMPUTED_VALUE"""),45293.6666666666) -> 45293.667 | C2: 5375 | D2: 5375 | E2: 5300 | F2: 5375 | G2: 20147500 | H2: 0 | I2: 0
A3: =IFERROR(__xludf.DUMMYFUNCTION("""COMPUTED_VALUE"""),45294.6666666666) -> 45294.667 | C3: 5375 | D3: 5400 | E3: 5325 | F3: 5350 | G3: 27547700 | H3: =(F3-F2)/F2 -> -0.0046511628 | I3: =(F3-$F$2)/$F$2 -> -0.0046511628
A4: =IFERROR(__xludf.DUMMYFUNCTION("""COMPUTED_VALUE"""),45295.6666666666) -> 45295.667 | C4: 5350 | D4: 5675 | E4: 5325 | F4: 5600 | G4: 77162400 | H4: =(F4-F3)/F3 -> 0.046728972 | I4: =(F4-$F$2)/$F$2 -> 0.041860465
A5: =IFERROR(__xludf.DUMMYFUNCTION("""COMPUTED_VALUE"""),45296.6666666666) -> 45296.667 | C5: 5675 | D5: 5750 | E5: 5575 | F5: 5575 | G5: 69463500 | H5: =(F5-F4)/F4 -> -0.0044642857 | I5: =(F5-$F$2)/$F$2 -> 0.037209302
A6: =IFERROR(__xludf.DUMMYFUNCTION("""COMPUTED_VALUE"""),45299.6666666666) -> 45299.667 | C6: 5575 | D6: 5650 | E6: 5550 | F6: 5575 | G6: 60606600 | H6: =(F6-F5)/F5 -> 0 | I6: =(F6-$F$2)/$F$2 -> 0.037209302
A7: =IFERROR(__xludf.DUMMYFUNCTION("""COMPUTED_VALUE"""),45300.6666666666) -> 45300.667 | C7: 5600 | D7: 5650 | E7: 5600 | F7: 5650 | G7: 34897000 | H7: =(F7-F6)/F6 -> 0.013452915 | I7: =(F7-$F$2)/$F$2 -> 0.051162791
A8: =IFERROR(__xludf.DUMMYFUNCTION("""COMPUTED_VALUE"""),45301.6666666666) -> 45301.667 | C8: 5625 | D8: 5675 | E8: 5575 | F8: 5600 | G8: 37988500 | H8: =(F8-F7)/F7 -> -0.0088495575 | I8: =(F8-$F$2)/$F$2 -> 0.041860465
A9: =IFERROR(__xludf.DUMMYFUNCTION("""COMPUTED_VALUE"""),45302.6666666666) -> 45302.667 | C9: 5650 | D9: 5700 | E9: 5575 | F9: 5600 | G9: 22855800 | H9: =(F9-F8)/F8 -> 0 | I9: =(F9-$F$2)/$F$2 -> 0.041860465
A10: =IFERROR(__xludf.DUMMYFUNCTION("""COMPUTED_VALUE"""),45303.6666666666) -> 45303.667 | C10: 5600 | D10: 5650 | E10: 5575 | F10: 5600 | G10: 40942900 | H10: =(F10-F9)/F9 -> 0 | I10: =(F10-$F$2)/$F$2 -> 0.041860465
A11: =IFERROR(__xludf.DUMMYFUNCTION("""COMPUTED_VALUE"""),45306.6666666666) -> 45306.667 | C11: 5650 | D11: 5675 | E11: 5600 | F11: 5625 | G11: 51408800 | H11: =(F11-F10)/F10 -> 0.0044642857 | I11: =(F11-$F$2)/$F$2 -> 0.046511628
A12: =IFERROR(__xludf.DUMMYFUNCTION("""COMPUTED_VALUE"""),45307.6666666666) -> 45307.667 | C12: 5625 | D12: 5625 | E12: 5575 | F12: 5600 | G12: 37795700 | H12: =(F12-F11)/F11 -> -0.0044444444 | I12: =(F12-$F$2)/$F$2 -> 0.041860465
A13: =IFERROR(__xludf.DUMMYFUNCTION("""COMPUTED_VALUE"""),45308.6666666666) -> 45308.667 | C13: 5600 | D13: 5625 | E13: 5475 | F13: 5550 | G13: 61481200 | H13: =(F13-F12)/F12 -> -0.0089285714 | I13: =(F13-$F$2)/$F$2 -> 0.03255814
A14: =IFERROR(__xludf.DUMMYFUNCTION("""COMPUTED_VALUE"""),45309.6666666666) -> 45309.667 | C14: 5550 | D14: 5600 | E14: 5475 | F14: 5550 | G14: 33241700 | H14: =(F14-F13)/F13 -> 0 | I14: =(F14-$F$2)/$F$2 -> 0.03255814
A15: =IFERROR(__xludf.DUMMYFUNCTION("""COMPUTED_VALUE"""),45310.6666666666) -> 45310.667 | C15: 5575 | D15: 5575 | E15: 5475 | F15: 5500 | G15: 29776100 | H15: =(F15-F14)/F14 -> -0.009009009 | I15: =(F15-$F$2)/$F$2 -> 0.023255814
A16: =IFERROR(__xludf.DUMMYFUNCTION("""COMPUTED_VALUE"""),45313.6666666666) -> 45313.667 | C16: 5525 | D16: 5600 | E16: 5450 | F16: 5525 | G16: 30949600 | H16: =(F16-F15)/F15 -> 0.0045454545 | I16: =(F16-$F$2)/$F$2 -> 0.027906977
A17: =IFERROR(__xludf.DUMMYFUNCTION("""COMPUTED_VALUE"""),45314.6666666666) -> 45314.667 | C17: 5525 | D17: 5525 | E17: 5375 | F17: 5425 | G17: 48824300 | H17: =(F17-F16)/F16 -> -0.018099548 | I17: =(F17-$F$2)/$F$2 -> 0.0093023256
A18: =IFERROR(__xludf.DUMMYFUNCTION("""COMPUTED_VALUE"""),45315.6666666666) -> 45315.667 | C18: 5450 | D18: 5500 | E18: 5400 | F18: 5475 | G18: 42436800 | H18: =(F18-F17)/F17 -> 0.0092165899 | I18: =(F18-$F$2)/$F$2 -> 0.018604651
A19: =IFERROR(__xludf.DUMMYFUNCTION("""COMPUTED_VALUE"""),45316.6666666666) -> 45316.667 | C19: 5500 | D19: 5525 | E19: 5400 | F19: 5400 | G19: 47955600 | H19: =(F19-F18)/F18 -> -0.01369863 | I19: =(F19-$F$2)/$F$2 -> 0.0046511628
A20: =IFERROR(__xludf.DUMMYFUNCTION("""COMPUTED_VALUE"""),45317.6666666666) -> 45317.667 | C20: 5400 | D20: 5425 | E20: 5350 | F20: 5425 | G20: 30545600 | H20: =(F20-F19)/F19 -> 0.0046296296 | I20: =(F20-$F$2)/$F$2 -> 0.0093023256
A21: =IFERROR(__xludf.DUMMYFUNCTION("""COMPUTED_VALUE"""),45320.6666666666) -> 45320.667 | C21: 5450 | D21: 5575 | E21: 5450 | F21: 5575 | G21: 63056100 | H21: =(F21-F20)/F20 -> 0.02764977 | I21: =(F21-$F$2)/$F$2 -> 0.037209302
A22: =IFERROR(__xludf.DUMMYFUNCTION("""COMPUTED_VALUE"""),45321.6666666666) -> 45321.667 | C22: 5575 | D22: 5675 | E22: 5550 | F22: 5650 | G22: 55020500 | H22: =(F22-F21)/F21 -> 0.013452915 | I22: =(F22-$F$2)/$F$2 -> 0.051162791
A23: =IFERROR(__xludf.DUMMYFUNCTION("""COMPUTED_VALUE"""),45322.6666666666) -> 45322.667 | C23: 5700 | D23: 5800 | E23: 5675 | F23: 5750 | G23: 70045600 | H23: =(F23-F22)/F22 -> 0.017699115 | I23: =(F23-$F$2)/$F$2 -> 0.069767442
A24: =IFERROR(__xludf.DUMMYFUNCTION("""COMPUTED_VALUE"""),45323.6666666666) -> 45323.667 | C24: 5750 | D24: 5750 | E24: 5650 | F24: 5725 | G24: 49179400 | H24: =(F24-F23)/F23 -> -0.0043478261 | I24: =(F24-$F$2)/$F$2 -> 0.065116279
A25: =IFERROR(__xludf.DUMMYFUNCTION("""COMPUTED_VALUE"""),45324.6666666666) -> 45324.667 | C25: 5750 | D25: 5825 | E25: 5750 | F25: 5775 | G25: 44074200 | H25: =(F25-F24)/F24 -> 0.0087336245 | I25: =(F25-$F$2)/$F$2 -> 0.074418605
A26: =IFERROR(__xludf.DUMMYFUNCTION("""COMPUTED_VALUE"""),45327.6666666666) -> 45327.667 | C26: 5775 | D26: 5825 | E26: 5725 | F26: 5750 | G26: 47096400 | H26: =(F26-F25)/F25 -> -0.0043290043 | I26: =(F26-$F$2)/$F$2 -> 0.069767442
A27: =IFERROR(__xludf.DUMMYFUNCTION("""COMPUTED_VALUE"""),45328.6666666666) -> 45328.667 | C27: 5775 | D27: 5825 | E27: 5750 | F27: 5775 | G27: 41834000 | H27: =(F27-F26)/F26 -> 0.0043478261 | I27: =(F27-$F$2)/$F$2 -> 0.074418605
A28: =IFERROR(__xludf.DUMMYFUNCTION("""COMPUTED_VALUE"""),45329.6666666666) -> 45329.667 | C28: 5775 | D28: 5825 | E28: 5750 | F28: 5750 | G28: 39906900 | H28: =(F28-F27)/F27 -> -0.0043290043 | I28: =(F28-$F$2)/$F$2 -> 0.069767442
A29: =IFERROR(__xludf.DUMMYFUNCTION("""COMPUTED_VALUE"""),45334.6666666666) -> 45334.667 | C29: 5775 | D29: 6000 | E29: 5750 | F29: 5950 | G29: 64615800 | H29: =(F29-F28)/F28 -> 0.034782609 | I29: =(F29-$F$2)/$F$2 -> 0.10697674
A30: =IFERROR(__xludf.DUMMYFUNCTION("""COMPUTED_VALUE"""),45335.6666666666) -> 45335.667 | C30: 5975 | D30: 5975 | E30: 5850 | F30: 5875 | G30: 74976200 | H30: =(F30-F29)/F29 -> -0.012605042 | I30: =(F30-$F$2)/$F$2 -> 0.093023256
A31: =IFERROR(__xludf.DUMMYFUNCTION("""COMPUTED_VALUE"""),45337.6666666666) -> 45337.667 | C31: 6150 | D31: 6225 | E31: 6000 | F31: 6000 | G31: 128792500 | H31: =(F31-F30)/F30 -> 0.021276596 | I31: =(F31-$F$2)/$F$2 -> 0.11627907
A32: =IFERROR(__xludf.DUMMYFUNCTION("""COMPUTED_VALUE"""),45338.6666666666) -> 45338.667 | C32: 6025 | D32: 6125 | E32: 6000 | F32: 6000 | G32: 62601000 | H32: =(F32-F31)/F31 -> 0 | I32: =(F32-$F$2)/$F$2 -> 0.11627907
A33: =IFERROR(__xludf.DUMMYFUNCTION("""COMPUTED_VALUE"""),45341.6666666666) -> 45341.667 | C33: 6025 | D33: 6050 | E33: 5875 | F33: 5875 | G33: 67950100 | H33: =(F33-F32)/F32 -> -0.020833333 | I33: =(F33-$F$2)/$F$2 -> 0.093023256
A34: =IFERROR(__xludf.DUMMYFUNCTION("""COMPUTED_VALUE"""),45342.6666666666) -> 45342.667 | C34: 5900 | D34: 6025 | E34: 5900 | F34: 6025 | G34: 37554100 | H34: =(F34-F33)/F33 -> 0.025531915 | I34: =(F34-$F$2)/$F$2 -> 0.12093023
A35: =IFERROR(__xludf.DUMMYFUNCTION("""COMPUTED_VALUE"""),45343.6666666666) -> 45343.667 | C35: 6025 | D35: 6050 | E35: 5925 | F35: 6000 | G35: 54476400 | H35: =(F35-F34)/F34 -> -0.0041493776 | I35: =(F35-$F$2)/$F$2 -> 0.11627907
A36: =IFERROR(__xludf.DUMMYFUNCTION("""COMPUTED_VALUE"""),45344.6666666666) -> 45344.667 | C36: 6000 | D36: 6025 | E36: 5900 | F36: 5950 | G36: 37676100 | H36: =(F36-F35)/F35 -> -0.0083333333 | I36: =(F36-$F$2)/$F$2 -> 0.10697674
A37: =IFERROR(__xludf.DUMMYFUNCTION("""COMPUTED_VALUE"""),45345.6666666666) -> 45345.667 | C37: 6000 | D37: 6000 | E37: 5825 | F37: 5900 | G37: 50216600 | H37: =(F37-F36)/F36 -> -0.0084033613 | I37: =(F37-$F$2)/$F$2 -> 0.097674419
A38: =IFERROR(__xludf.DUMMYFUNCTION("""COMPUTED_VALUE"""),45348.6666666666) -> 45348.667 | C38: 5900 | D38: 5925 | E38: 5800 | F38: 5900 | G38: 27500000 | H38: =(F38-F37)/F37 -> 0 | I38: =(F38-$F$2)/$F$2 -> 0.097674419
A39: =IFERROR(__xludf.DUMMYFUNCTION("""COMPUTED_VALUE"""),45349.6666666666) -> 45349.667 | C39: 5900 | D39: 6000 | E39: 5850 | F39: 6000 | G39: 38645200 | H39: =(F39-F38)/F38 -> 0.016949153 | I39: =(F39-$F$2)/$F$2 -> 0.11627907
A40: =IFERROR(__xludf.DUMMYFUNCTION("""COMPUTED_VALUE"""),45350.6666666666) -> 45350.667 | C40: 5950 | D40: 6000 | E40: 5900 | F40: 5975 | G40: 27278600 | H40: =(F40-F39)/F39 -> -0.0041666667 | I40: =(F40-$F$2)/$F$2 -> 0.11162791
...

Sheet Kurs USD ke IDR
A1: Date | C1: Close
A2: =IFERROR(__xludf.DUMMYFUNCTION("""COMPUTED_VALUE"""),45292.9986111111) -> 45292.999 | C2: 15383
A3: =IFERROR(__xludf.DUMMYFUNCTION("""COMPUTED_VALUE"""),45293.9986111111) -> 45293.999 | C3: 15498
A4: =IFERROR(__xludf.DUMMYFUNCTION("""COMPUTED_VALUE"""),45294.9986111111) -> 45294.999 | C4: 15555
A5: =IFERROR(__xludf.DUMMYFUNCTION("""COMPUTED_VALUE"""),45295.9986111111) -> 45295.999 | C5: 15511
A6: =IFERROR(__xludf.DUMMYFUNCTION("""COMPUTED_VALUE"""),45296.9986111111) -> 45296.999 | C6: 15477.5
A7: =IFERROR(__xludf.DUMMYFUNCTION("""COMPUTED_VALUE"""),45297.9986111111) -> 45297.999 | C7: 15477.5
A8: =IFERROR(__xludf.DUMMYFUNCTION("""COMPUTED_VALUE"""),45298.9986111111) -> 45298.999 | C8: 15477.5
A9: =IFERROR(__xludf.DUMMYFUNCTION("""COMPUTED_VALUE"""),45299.9986111111) -> 45299.999 | C9: 15495.5
A10: =IFERROR(__xludf.DUMMYFUNCTION("""COMPUTED_VALUE"""),45300.9986111111) -> 45300.999 | C10: 15534.5
A11: =IFERROR(__xludf.DUMMYFUNCTION("""COMPUTED_VALUE"""),45301.9986111111) -> 45301.999 | C11: 15555
A12: =IFERROR(__xludf.DUMMYFUNCTION("""COMPUTED_VALUE"""),45302.9986111111) -> 45302.999 | C12: 15556.5
A13: =IFERROR(__xludf.DUMMYFUNCTION("""COMPUTED_VALUE"""),45303.9986111111) -> 45303.999 | C13: 15503.2
A14: =IFERROR(__xludf.DUMMYFUNCTION("""COMPUTED_VALUE"""),45304.9986111111) -> 45304.999 | C14: 15503.2
A15: =IFERROR(__xludf.DUMMYFUNCTION("""COMPUTED_VALUE"""),45305.9986111111) -> 45305.999 | C15: 15503.2
A16: =IFERROR(__xludf.DUMMYFUNCTION("""COMPUTED_VALUE"""),45306.9986111111) -> 45306.999 | C16: 15546
A17: =IFERROR(__xludf.DUMMYFUNCTION("""COMPUTED_VALUE"""),45307.9986111111) -> 45307.999 | C17: 15625
A18: =IFERROR(__xludf.DUMMYFUNCTION("""COMPUTED_VALUE"""),45308.9986111111) -> 45308.999 | C18: 15624
A19: =IFERROR(__xludf.DUMMYFUNCTION("""COMPUTED_VALUE"""),45309.9986111111) -> 45309.999 | C19: 15613.1
A20: =IFERROR(__xludf.DUMMYFUNCTION("""COMPUTED_VALUE"""),45310.9986111111) -> 45310.999 | C20: 15601
A21: =IFERROR(__xludf.DUMMYFUNCTION("""COMPUTED_VALUE"""),45311.9986111111) -> 45311.999 | C21: 15601
A22: =IFERROR(__xludf.DUMMYFUNCTION("""COMPUTED_VALUE"""),45312.9986111111) -> 45312.999 | C22: 15601
A23: =IFERROR(__xludf.DUMMYFUNCTION("""COMPUTED_VALUE"""),45313.9986111111) -> 45313.999 | C23: 15655.5
A24: =IFERROR(__xludf.DUMMYFUNCTION("""COMPUTED_VALUE"""),45314.9986111111) -> 45314.999 | C24: 15715
A25: =IFERROR(__xludf.DUMMYFUNCTION("""COMPUTED_VALUE"""),45315.9986111111) -> 45315.999 | C25: 15714.5
A26: =IFERROR(__xludf.DUMMYFUNCTION("""COMPUTED_VALUE"""),45316.9986111111) -> 45316.999 | C26: 15808
A27: =IFERROR(__xludf.DUMMYFUNCTION("""COMPUTED_VALUE"""),45317.9986111111) -> 45317.999 | C27: 15767.6
A28: =IFERROR(__xludf.DUMMYFUNCTION("""COMPUTED_VALUE"""),45318.9986111111) -> 45318.999 | C28: 15767.6
A29: =IFERROR(__xludf.DUMMYFUNCTION("""COMPUTED_VALUE"""),45319.9986111111) -> 45319.999 | C29: 15767.6
A30: =IFERROR(__xludf.DUMMYFUNCTION("""COMPUTED_VALUE"""),45320.9986111111) -> 45320.999 | C30: 15828
A31: =IFERROR(__xludf.DUMMYFUNCTION("""COMPUTED_VALUE"""),45321.9986111111) -> 45321.999 | C31: 15785
A32: =IFERROR(__xludf.DUMMYFUNCTION("""COMPUTED_VALUE"""),45322.9986111111) -> 45322.999 | C32: 15769
A33: =IFERROR(__xludf.DUMMYFUNCTION("""COMPUTED_VALUE"""),45323.9986111111) -> 45323.999 | C33: 15726
A34: =IFERROR(__xludf.DUMMYFUNCTION("""COMPUTED_VALUE"""),45324.9986111111) -> 45324.999 | C34: 15727.2
A35: =IFERROR(__xludf.DUMMYFUNCTION("""COMPUTED_VALUE"""),45325.9986111111) -> 45325.999 | C35: 15727.2
A36: =IFERROR(__xludf.DUMMYFUNCTION("""COMPUTED_VALUE"""),45326.9986111111) -> 45326.999 | C36: 15727.2
A37: =IFERROR(__xludf.DUMMYFUNCTION("""COMPUTED_VALUE"""),45327.9986111111) -> 45327.999 | C37: 15711.5
A38: =IFERROR(__xludf.DUMMYFUNCTION("""COMPUTED_VALUE"""),45328.9986111111) -> 45328.999 | C38: 15733
A39: =IFERROR(__xludf.DUMMYFUNCTION("""COMPUTED_VALUE"""),45329.9986111111) -> 45329.999 | C39: 15647
A40: =IFERROR(__xludf.DUMMYFUNCTION("""COMPUTED_VALUE"""),45330.9986111111) -> 45330.999 | C40: 15660.3
...

Sheet IHSG
A1: Date | B1: Close
A2: =IFERROR(__xludf.DUMMYFUNCTION("""COMPUTED_VALUE"""),45293.6666666666) -> 45293.667 | B2: 7323.59
A3: =IFERROR(__xludf.DUMMYFUNCTION("""COMPUTED_VALUE"""),45294.6666666666) -> 45294.667 | B3: 7279.09
A4: =IFERROR(__xludf.DUMMYFUNCTION("""COMPUTED_VALUE"""),45295.6666666666) -> 45295.667 | B4: 7359.76
A5: =IFERROR(__xludf.DUMMYFUNCTION("""COMPUTED_VALUE"""),45296.6666666666) -> 45296.667 | B5: 7350.62
A6: =IFERROR(__xludf.DUMMYFUNCTION("""COMPUTED_VALUE"""),45299.6666666666) -> 45299.667 | B6: 7283.58
A7: =IFERROR(__xludf.DUMMYFUNCTION("""COMPUTED_VALUE"""),45300.6666666666) -> 45300.667 | B7: 7200.2
A8: =IFERROR(__xludf.DUMMYFUNCTION("""COMPUTED_VALUE"""),45301.6666666666) -> 45301.667 | B8: 7227.3
A9: =IFERROR(__xludf.DUMMYFUNCTION("""COMPUTED_VALUE"""),45302.6666666666) -> 45302.667 | B9: 7219.96
A10: =IFERROR(__xludf.DUMMYFUNCTION("""COMPUTED_VALUE"""),45303.6666666666) -> 45303.667 | B10: 7241.14
A11: =IFERROR(__xludf.DUMMYFUNCTION("""COMPUTED_VALUE"""),45306.6666666666) -> 45306.667 | B11: 7224
A12: =IFERROR(__xludf.DUMMYFUNCTION("""COMPUTED_VALUE"""),45307.6666666666) -> 45307.667 | B12: 7242.79
A13: =IFERROR(__xludf.DUMMYFUNCTION("""COMPUTED_VALUE"""),45308.6666666666) -> 45308.667 | B13: 7200.64
A14: =IFERROR(__xludf.DUMMYFUNCTION("""COMPUTED_VALUE"""),45309.6666666666) -> 45309.667 | B14: 7252.97
A15: =IFERROR(__xludf.DUMMYFUNCTION("""COMPUTED_VALUE"""),45310.6666666666) -> 45310.667 | B15: 7227.4
A16: =IFERROR(__xludf.DUMMYFUNCTION("""COMPUTED_VALUE"""),45313.6666666666) -> 45313.667 | B16: 7247.93
A17: =IFERROR(__xludf.DUMMYFUNCTION("""COMPUTED_VALUE"""),45314.6666666666) -> 45314.667 | B17: 7256.23
A18: =IFERROR(__xludf.DUMMYFUNCTION("""COMPUTED_VALUE"""),45315.6666666666) -> 45315.667 | B18: 7227.82
A19: =IFERROR(__xludf.DUMMYFUNCTION("""COMPUTED_VALUE"""),45316.6666666666) -> 45316.667 | B19: 7178.04
A20: =IFERROR(__xludf.DUMMYFUNCTION("""COMPUTED_VALUE"""),45317.6666666666) -> 45317.667 | B20: 7137.09
A21: =IFERROR(__xludf.DUMMYFUNCTION("""COMPUTED_VALUE"""),45320.6666666666) -> 45320.667 | B21: 7157.18
A22: =IFERROR(__xludf.DUMMYFUNCTION("""COMPUTED_VALUE"""),45321.6666666666) -> 45321.667 | B22: 7192.22
A23: =IFERROR(__xludf.DUMMYFUNCTION("""COMPUTED_VALUE"""),45322.6666666666) -> 45322.667 | B23: 7207.94
A24: =IFERROR(__xludf.DUMMYFUNCTION("""COMPUTED_VALUE"""),45323.6666666666) -> 45323.667 | B24: 7201.7
A25: =IFERROR(__xludf.DUMMYFUNCTION("""COMPUTED_VALUE"""),45324.6666666666) -> 45324.667 | B25: 7238.79
A26: =IFERROR(__xludf.DUMMYFUNCTION("""COMPUTED_VALUE"""),45327.6666666666) -> 45327.667 | B26: 7198.62
A27: =IFERROR(__xludf.DUMMYFUNCTION("""COMPUTED_VALUE"""),45328.6666666666) -> 45328.667 | B27: 7247.41
A28: =IFERROR(__xludf.DUMMYFUNCTION("""COMPUTED_VALUE"""),45329.6666666666) -> 45329.667 | B28: 7235.15
A29: =IFERROR(__xludf.DUMMYFUNCTION("""COMPUTED_VALUE"""),45334.6666666666) -> 45334.667 | B29: 7297.67
A30: =IFERROR(__xludf.DUMMYFUNCTION("""COMPUTED_VALUE"""),45335.6666666666) -> 45335.667 | B30: 7209.74
A31: =IFERROR(__xludf.DUMMYFUNCTION("""COMPUTED_VALUE"""),45337.6666666666) -> 45337.667 | B31: 7303.28
A32: =IFERROR(__xludf.DUMMYFUNCTION("""COMPUTED_VALUE"""),45338.6666666666) -> 45338.667 | B32: 7335.55
A33: =IFERROR(__xludf.DUMMYFUNCTION("""COMPUTED_VALUE"""),45341.6666666666) -> 45341.667 | B33: 7296.7
A34: =IFERROR(__xludf.DUMMYFUNCTION("""COMPUTED_VALUE"""),45342.6666666666) -> 45342.667 | B34: 7352.6
A35: =IFERROR(__xludf.DUMMYFUNCTION("""COMPUTED_VALUE"""),45343.6666666666) -> 45343.667 | B35: 7349.02
A36: =IFERROR(__xludf.DUMMYFUNCTION("""COMPUTED_VALUE"""),45344.6666666666) -> 45344.667 | B36: 7339.64
A37: =IFERROR(__xludf.DUMMYFUNCTION("""COMPUTED_VALUE"""),45345.6666666666) -> 45345.667 | B37: 7295.1
A38: =IFERROR(__xludf.DUMMYFUNCTION("""COMPUTED_VALUE"""),45348.6666666666) -> 45348.667 | B38: 7283.82
A39: =IFERROR(__xludf.DUMMYFUNCTION("""COMPUTED_VALUE"""),45349.6666666666) -> 45349.667 | B39: 7285.32
A40: =IFERROR(__xludf.DUMMYFUNCTION("""COMPUTED_VALUE"""),45350.6666666666) -> 45350.667 | B40: 7328.64
...

Sheet FUNDAMENTAL
A1: Kode Saham | B1: Tahun | C1: Market Cap (Triliun Rp) | D1: ROE (%) | E1: PER (x) | F1: PBV (x) | G1: Net Profit (Triliun Rp)
A2: BBCA.JK | B2: 2024 | C2: 1150 | D2: 21,80% | E2: 20,98 | F2: 3,85 | G2: 54,84
A3: BBCA.JK | B3: 2025 | C3: 915.3 | D3: 20,43% | E3: 15,90 | F3: 3,25 | G3: 57,54
A5: BBRI.JK | B5: 2024 | C5: 725 | D5: 18,90% | E5: 12,09 | F5: 2,24 | G5: 59,94
A6: BBRI.JK | B6: 2025 | C6: 588.1 | D6: 17,12% | E6: 10,38 | F6: 1,78 | G6: 56,65
A8: BMRI.JK | B8: 2024 | C8: 466.6 | D8: 17,79% | E8: 8,36 | F8: 1,49 | G8: 55,78
A9: BMRI.JK | B9: 2025 | C9: 466.6 | D9: 17,19% | E9: 8,29 | F9: 1,43 | G9: 56,29
A11: BBNI.JK | B11: 2024 | C11: 185.5 | D11: 14,20% | E11: 8,64 | F11: 1,11 | G11: 21,46
A12: BBNI.JK | B12: 2025 | C12: 170.9 | D12: 11,36% | E12: 8,53 | F12: 0,97 | G12: 20,04

Sheet Volatilitas
A1: KODE SAHAM | B1: 2024 | C1: 2025 | D1: KETERANGAN
A2: BBRI | B2: =_xlfn.STDEV.P(BBRI!$H$2:$H$238) -> 0.018331385 | C2: =_xlfn.STDEV.P(BBRI!$H$238:$H$474) -> 0.023397875
A3: BBCA | B3: =_xlfn.STDEV.P(BBCA!$H$2:$H$238) -> 0.013942419 | C3: =_xlfn.STDEV.P(BBCA!$H$238:$H$474) -> 0.018476211
A4: BMRI | B4: =_xlfn.STDEV.P(BMRI!$H$2:$H$238) -> 0.01917473 | C4: =_xlfn.STDEV.P(BMRI!$H$238:$H$474) -> 0.023559962
A5: BBNI | B5: =_xlfn.STDEV.P(BBNI!$H$2:$H$238) -> 0.019025427 | C5: =_xlfn.STDEV.P(BBNI!$H$238:$H$474) -> 0.024222997
